<?xml version='1.0'?>
<sdf version='1.9'>
    <world name="planar_world">
    <model name="PPR">
        <static>false</static>
        
        <link name="l1">
            <pose>0 -0.5 0 -1.5707 0 0</pose>

            <inertial>
                <inertia>
                        <ixx>1</ixx>
                        <ixy>0</ixy>
                        <ixz>0</ixz>
                        <iyy>1</iyy>
                        <iyz>0</iyz>
                        <izz>1</izz>
                </inertia>
                <mass>1.0</mass>
            </inertial>
            <collision name="l1_collision">
                <geometry>
                    <box>
                        <size>0.05 0.09 1</size>
                    </box>
                </geometry>
            </collision>
            <visual name="l1_visual">
                <geometry>
                    <box>
                        <size>0.05 0.09 1</size>
                    </box>
                </geometry>
            </visual>
            <visual name='joint_case1'>
                <pose>0 0 0.5 0 0 0</pose>
                <geometry>
                    <sphere>
                        <radius>0.05</radius>
                    </sphere>
                </geometry>
            </visual>
        </link>
    
        <link name="l2">
            <pose relative_to='l1'>-0.50 0 0.5  1.5707 0 1.5707</pose>            

            <inertial>
                <inertia>
                    <ixx>1</ixx>
                    <ixy>0</ixy>
                    <ixz>0</ixz>
                    <iyy>1</iyy>
                    <iyz>0</iyz>
                    <izz>1</izz>
                </inertia>
                <mass>1.0</mass>
            </inertial>
            <collision name="l2_collision">
                <geometry>
                    <box>
                        <size>0.05 0.09 1</size>
                    </box>
                </geometry>
            </collision>

            <visual name="l2_visual">
                <geometry>
                    <box>
                        <size>0.05 0.09 1</size>
                    </box>
                </geometry>
                <material>
                    <diffuse>0.98 0.22 0.1 0.6</diffuse>
                </material>
            </visual>
            <visual name='joint_case2'>
            <pose >0 0 0.5 0 0 0</pose>
                <geometry>
                    <sphere>
                        <radius>0.05</radius>
                    </sphere>
                </geometry>
            </visual>
        </link>


        <link name="l3">
            <pose relative_to='l2'>0 0 0.75 0 0 0</pose>
    
            <inertial>
                <inertia>
                    <ixx>1</ixx>
                    <ixy>0</ixy>
                    <ixz>0</ixz>
                    <iyy>1</iyy>
                    <iyz>0</iyz>
                    <izz>1</izz>
                </inertia>
                <mass>1.0</mass>
            </inertial>
            <collision name="l3_collision">
                <geometry>
                    <cylinder>
                        <radius>0.07</radius>
                        <length>0.5</length>
                    </cylinder>
                </geometry>
            </collision>
            <visual name="l3_visual">
                    <geometry>
                        <cylinder>
                            <radius>0.03</radius>
                            <length>0.5</length>
                        </cylinder>
                    </geometry>
            </visual>
        </link>


        <joint name='q1' type="prismatic">
            <pose>0 0 0 0 0 0</pose>
            <parent>world</parent>
            <child>l1</child>
            <axis>
                <xyz>0 0 1</xyz>
                <limit>
                    <lower>0</lower>
                    <upper>0.5</upper>
                </limit>
                <dynamics>
                    <damping>0.2</damping>
                    <friction>0.1</friction>
                </dynamics>
            </axis>    
        </joint>

        <joint name='q2' type="prismatic">
            <pose relative_to='l2'>0 0 0 0 0 0</pose>
            
            <parent>l1</parent>
            <child>l2</child>
            <axis>
                <xyz>0 0 1</xyz>
                <limit>
                    <lower>0</lower>
                    <upper>0.5</upper>
                </limit>
                <dynamics>
                    <damping>0.2</damping>
                    <friction>0.1</friction>
                </dynamics>

            </axis>    
        </joint>

        <joint name='q3' type='revolute'>
            <pose relative_to="l3">0 0 -0.25 0  0 0</pose>
            <parent>l2</parent>
            <child>l3</child>
            <axis>
                <xyz>-1 0 0</xyz>
            <dynamics>
                    <damping>0.2</damping>
                    <friction>0.1</friction>
            </dynamics>
            </axis>
        </joint>
        


    </model>
    </world>
</sdf>

