<?xml version='1.0'?>
<sdf version='1.9'>
    <world name="planar_world">
    <model name="PRR">
        <static>false</static>
        
        <link name="l1">

            <pose>0 0 0  0 1.5707 0</pose>
            <collision name="l1_collision">
                <geometry>
                    <box>
                        <size>0.05 0.09 1</size>
                    </box>
                </geometry>
            </collision>


            <visual name="l1_visual">
                <geometry>
                    <box>
                        <size>0.05 0.09 1</size>
                    </box>
                </geometry>
            </visual>
            

        </link> 
                
        
        <link name="l2">
            <pose relative_to='l1'>0 0 0.75 0 0 0</pose>
            <!-- the 0.75 comes from h/2 of box + h/2 of cylinder-->
            <collision name="l2_collision">
                <geometry>
                    <cylinder>
                        <radius>0.05</radius>
                        <length>0.5</length>
                    </cylinder>
                </geometry>
            </collision>
           
            <visual name="l2_visual">
                <geometry>
                    <cylinder>
                        <radius>0.05</radius>
                        <length>0.5</length>
                    </cylinder>
                </geometry>
            </visual>

            <visual name="l2_joint_case">

                <pose>0 0 -0.25 0 -1.5707  0 </pose>
                <geometry>
                    <cylinder>
                        <radius>0.07</radius>
                        <length>0.10</length>
                    </cylinder>
                </geometry>
                <material>
                    <diffuse>0.98 0.22 0.1 1</diffuse>
                </material>
            </visual>
            <visual name="l2_joint_case_pt2">

                <pose>0 0 -0.25 0 -1.5707  0 </pose>
                <geometry>
                    <sphere>
                        <radius>0.08</radius>
                    </sphere>
                </geometry>
            </visual>
        </link>

            
        
        
        <link name="l3">
            <pose relative_to='l2'>0 0 0.5 0 0 0</pose>
            <collision name="l3_collision">
                <geometry>
                    <cylinder>
                        <radius>0.07</radius>
                        <length>0.5</length>
                    </cylinder>
                </geometry>
            </collision>

            <visual name="l3_visual">
                <geometry>
                    <cylinder>
                        <radius>0.03</radius>
                        <length>0.5</length>
                    </cylinder>
                </geometry>
            </visual>
            <visual name="l3_joint_case">
                <pose>0 0 -0.25 0 -1.5707 0</pose>
                <geometry>
                    <cylinder>
                        <radius>0.05</radius>
                        <length>0.1</length>
                    </cylinder>
                </geometry>
                 <material>
                    <diffuse>0.98 0.22 0.1 1</diffuse>
                </material>
            </visual>
            <visual name="l3_joint_case_pt2">
                <pose>0 0 -0.25 0 -1.5707 0</pose>
                <geometry>
                    <sphere>
                        <radius>0.06</radius>
                    </sphere>
                </geometry>
            </visual>

        </link>
        
        <joint name='q1' type="prismatic">
            <pose>0 0 0 0 0 0</pose>
            <parent>world</parent>
            <child>l1</child>
            <axis>
                <xyz>0 0 1</xyz>
                <limit>
                    <lower>-0.5</lower>
                    <upper>0.5</upper>
                </limit>
            </axis>    
        </joint>

        <joint name='q2' type='revolute'>
            <pose relative_to="l2">0 0 -0.25 0 -1.5707 0</pose>
            <parent>l1</parent>
            <child>l2</child>
            <axis>
                <xyz>0 0 1</xyz>
                <limit>
                    <lower>0.0</lower>
                    <upper>3.14</upper>
                </limit>
            </axis>
        </joint>
        
        
        <joint name='q3' type='revolute'>
            <pose>0 0 -0.25 0 1.5707 0 </pose>
            <parent>l2</parent>
            <child>l3</child>
            
            <axis>
                <xyz>0 0 1</xyz>
                <limit>
                    <lower>0</lower>
                    <upper>3.14</upper>
                </limit>
            </axis>
        </joint>
    

    </model>
    </world>
</sdf>

